
2017-09-04 23:44:48,522 INFO: errors [in app.py:142]
2017-09-04 23:45:26,625 INFO: errors [in app.py:142]
2017-09-04 23:46:03,823 INFO: errors [in app.py:142]
2017-09-04 23:46:14,967 ERROR: Exception on /api/v1.0/check_song [POST] [in /usr/lib/python2.7/site-packages/flask/app.py:1423]
Traceback (most recent call last):
  File "/usr/lib/python2.7/site-packages/flask/app.py", line 1817, in wsgi_app
    response = self.full_dispatch_request()
  File "/usr/lib/python2.7/site-packages/flask/app.py", line 1477, in full_dispatch_request
    rv = self.handle_user_exception(e)
  File "/usr/lib/python2.7/site-packages/flask/app.py", line 1381, in handle_user_exception
    reraise(exc_type, exc_value, tb)
  File "/usr/lib/python2.7/site-packages/flask/app.py", line 1475, in full_dispatch_request
    rv = self.dispatch_request()
  File "/usr/lib/python2.7/site-packages/flask/app.py", line 1461, in dispatch_request
    return self.view_functions[rule.endpoint](**req.view_args)
  File "app.py", line 99, in check_song
    if Song.query.filter_by(name=name).first().id:
AttributeError: 'NoneType' object has no attribute 'id'
2017-09-04 23:47:05,347 INFO: errors [in app.py:142]
2017-09-05 00:19:05,020 INFO: errors [in app.py:145]
2017-09-05 00:19:17,486 INFO: errors [in app.py:145]
2017-09-05 00:19:34,236 ERROR: Exception on /api/v1.0/update_user [POST] [in /usr/lib/python2.7/site-packages/flask/app.py:1423]
Traceback (most recent call last):
  File "/usr/lib/python2.7/site-packages/flask/app.py", line 1817, in wsgi_app
    response = self.full_dispatch_request()
  File "/usr/lib/python2.7/site-packages/flask/app.py", line 1477, in full_dispatch_request
    rv = self.handle_user_exception(e)
  File "/usr/lib/python2.7/site-packages/flask/app.py", line 1381, in handle_user_exception
    reraise(exc_type, exc_value, tb)
  File "/usr/lib/python2.7/site-packages/flask/app.py", line 1475, in full_dispatch_request
    rv = self.dispatch_request()
  File "/usr/lib/python2.7/site-packages/flask/app.py", line 1461, in dispatch_request
    return self.view_functions[rule.endpoint](**req.view_args)
  File "app.py", line 108, in update_user
    if User.query.filter_by(id=data['id']):
KeyError: 'id'
2017-09-05 00:19:42,012 INFO: errors [in app.py:145]
2017-09-05 00:20:09,315 ERROR: Exception on /api/v1.0/update_user [POST] [in /usr/lib/python2.7/site-packages/flask/app.py:1423]
Traceback (most recent call last):
  File "/usr/lib/python2.7/site-packages/flask/app.py", line 1817, in wsgi_app
    response = self.full_dispatch_request()
  File "/usr/lib/python2.7/site-packages/flask/app.py", line 1477, in full_dispatch_request
    rv = self.handle_user_exception(e)
  File "/usr/lib/python2.7/site-packages/flask/app.py", line 1381, in handle_user_exception
    reraise(exc_type, exc_value, tb)
  File "/usr/lib/python2.7/site-packages/flask/app.py", line 1475, in full_dispatch_request
    rv = self.dispatch_request()
  File "/usr/lib/python2.7/site-packages/flask/app.py", line 1461, in dispatch_request
    return self.view_functions[rule.endpoint](**req.view_args)
  File "app.py", line 108, in update_user
    if User.query.filter_by(id=data['id']):
KeyError: 'id'
2017-09-05 00:20:27,012 INFO: errors [in app.py:147]
2017-09-05 00:25:17,283 ERROR: Exception on /api/v1.0/update_user [POST] [in /usr/lib/python2.7/site-packages/flask/app.py:1423]
Traceback (most recent call last):
  File "/usr/lib/python2.7/site-packages/flask/app.py", line 1817, in wsgi_app
    response = self.full_dispatch_request()
  File "/usr/lib/python2.7/site-packages/flask/app.py", line 1475, in full_dispatch_request
    rv = self.dispatch_request()
  File "/usr/lib/python2.7/site-packages/flask/app.py", line 1381, in handle_user_exception
    reraise(exc_type, exc_value, tb)
  File "/usr/lib/python2.7/site-packages/flask/app.py", line 1475, in full_dispatch_request
    rv = self.dispatch_request()
  File "/usr/lib/python2.7/site-packages/flask/app.py", line 1461, in dispatch_request
    return self.view_functions[rule.endpoint](**req.view_args)
  File "app.py", line 110, in update_user
    if not User.query.filter_by(id=data['id']):
  File "app.py", line 110, in update_user
    if not User.query.filter_by(id=data['id']):
  File "/usr/lib64/python2.7/bdb.py", line 49, in trace_dispatch
    return self.dispatch_line(frame)
  File "/usr/lib64/python2.7/bdb.py", line 68, in dispatch_line
    if self.quitting: raise BdbQuit
BdbQuit
2017-09-05 00:25:21,923 INFO: errors [in app.py:148]
2017-09-05 00:26:24,909 ERROR: Exception on /api/v1.0/update_user [POST] [in /usr/lib/python2.7/site-packages/flask/app.py:1423]
Traceback (most recent call last):
  File "/usr/lib/python2.7/site-packages/flask/app.py", line 1817, in wsgi_app
    response = self.full_dispatch_request()
  File "/usr/lib/python2.7/site-packages/flask/app.py", line 1478, in full_dispatch_request
    response = self.make_response(rv)
  File "/usr/lib/python2.7/site-packages/flask/app.py", line 1566, in make_response
    raise ValueError('View function did not return a response')
ValueError: View function did not return a response
2017-09-05 00:26:59,154 ERROR: Exception on /api/v1.0/update_user [POST] [in /usr/lib/python2.7/site-packages/flask/app.py:1423]
Traceback (most recent call last):
  File "/usr/lib/python2.7/site-packages/flask/app.py", line 1817, in wsgi_app
    response = self.full_dispatch_request()
  File "/usr/lib/python2.7/site-packages/flask/app.py", line 1478, in full_dispatch_request
    response = self.make_response(rv)
  File "/usr/lib/python2.7/site-packages/flask/app.py", line 1566, in make_response
    raise ValueError('View function did not return a response')
ValueError: View function did not return a response
2017-09-05 00:27:00,622 ERROR: Exception on /api/v1.0/update_user [POST] [in /usr/lib/python2.7/site-packages/flask/app.py:1423]
Traceback (most recent call last):
  File "/usr/lib/python2.7/site-packages/flask/app.py", line 1817, in wsgi_app
    response = self.full_dispatch_request()
  File "/usr/lib/python2.7/site-packages/flask/app.py", line 1478, in full_dispatch_request
    response = self.make_response(rv)
  File "/usr/lib/python2.7/site-packages/flask/app.py", line 1566, in make_response
    raise ValueError('View function did not return a response')
ValueError: View function did not return a response
2017-09-05 00:27:16,109 ERROR: Exception on /api/v1.0/update_user [POST] [in /usr/lib/python2.7/site-packages/flask/app.py:1423]
Traceback (most recent call last):
  File "/usr/lib/python2.7/site-packages/flask/app.py", line 1817, in wsgi_app
    response = self.full_dispatch_request()
  File "/usr/lib/python2.7/site-packages/flask/app.py", line 1478, in full_dispatch_request
    response = self.make_response(rv)
  File "/usr/lib/python2.7/site-packages/flask/app.py", line 1566, in make_response
    raise ValueError('View function did not return a response')
ValueError: View function did not return a response
2017-09-05 00:28:26,829 INFO: errors [in app.py:148]
2017-09-05 00:28:28,696 ERROR: Exception on /api/v1.0/update_user [POST] [in /usr/lib/python2.7/site-packages/flask/app.py:1423]
Traceback (most recent call last):
  File "/usr/lib/python2.7/site-packages/flask/app.py", line 1817, in wsgi_app
    response = self.full_dispatch_request()
  File "/usr/lib/python2.7/site-packages/flask/app.py", line 1478, in full_dispatch_request
    response = self.make_response(rv)
  File "/usr/lib/python2.7/site-packages/flask/app.py", line 1566, in make_response
    raise ValueError('View function did not return a response')
ValueError: View function did not return a response
2017-09-05 00:30:06,140 INFO: errors [in app.py:149]
2017-09-05 00:30:07,881 ERROR: Exception on /api/v1.0/update_user [POST] [in /usr/lib/python2.7/site-packages/flask/app.py:1423]
Traceback (most recent call last):
  File "/usr/lib/python2.7/site-packages/flask/app.py", line 1817, in wsgi_app
    response = self.full_dispatch_request()
  File "/usr/lib/python2.7/site-packages/flask/app.py", line 1477, in full_dispatch_request
    rv = self.handle_user_exception(e)
  File "/usr/lib/python2.7/site-packages/flask/app.py", line 1381, in handle_user_exception
    reraise(exc_type, exc_value, tb)
  File "/usr/lib/python2.7/site-packages/flask/app.py", line 1475, in full_dispatch_request
    rv = self.dispatch_request()
  File "/usr/lib/python2.7/site-packages/flask/app.py", line 1461, in dispatch_request
    return self.view_functions[rule.endpoint](**req.view_args)
  File "app.py", line 111, in update_user
    if not User.query.filter_by(id=data['id']).first():
  File "/usr/lib64/python2.7/site-packages/sqlalchemy/orm/query.py", line 2630, in first
    ret = list(self[0:1])
  File "/usr/lib64/python2.7/site-packages/sqlalchemy/orm/query.py", line 2453, in __getitem__
    return list(res)
  File "/usr/lib64/python2.7/site-packages/sqlalchemy/orm/query.py", line 2732, in __iter__
    return self._execute_and_instances(context)
  File "/usr/lib64/python2.7/site-packages/sqlalchemy/orm/query.py", line 2747, in _execute_and_instances
    result = conn.execute(querycontext.statement, self._params)
  File "/usr/lib64/python2.7/site-packages/sqlalchemy/engine/base.py", line 914, in execute
    return meth(self, multiparams, params)
  File "/usr/lib64/python2.7/site-packages/sqlalchemy/sql/elements.py", line 323, in _execute_on_connection
    return connection._execute_clauseelement(self, multiparams, params)
  File "/usr/lib64/python2.7/site-packages/sqlalchemy/engine/base.py", line 1010, in _execute_clauseelement
    compiled_sql, distilled_params
  File "/usr/lib64/python2.7/site-packages/sqlalchemy/engine/base.py", line 1146, in _execute_context
    context)
  File "/usr/lib64/python2.7/site-packages/sqlalchemy/engine/base.py", line 1341, in _handle_dbapi_exception
    exc_info
  File "/usr/lib64/python2.7/site-packages/sqlalchemy/util/compat.py", line 200, in raise_from_cause
    reraise(type(exception), exception, tb=exc_tb)
  File "/usr/lib64/python2.7/site-packages/sqlalchemy/engine/base.py", line 1139, in _execute_context
    context)
  File "/usr/lib64/python2.7/site-packages/sqlalchemy/engine/default.py", line 450, in do_execute
    cursor.execute(statement, parameters)
OperationalError: (sqlite3.OperationalError) no such column: user.x [SQL: u'SELECT user.id AS user_id, user.x AS user_x, user.y AS user_y, user.requested_song AS user_requested_song \nFROM user \nWHERE user.id = ?\n LIMIT ? OFFSET ?'] [parameters: (u'123', 1, 0)]
2017-09-05 00:30:20,094 ERROR: Exception on /api/v1.0/update_user [POST] [in /usr/lib/python2.7/site-packages/flask/app.py:1423]
Traceback (most recent call last):
  File "/usr/lib/python2.7/site-packages/flask/app.py", line 1817, in wsgi_app
    response = self.full_dispatch_request()
  File "/usr/lib/python2.7/site-packages/flask/app.py", line 1477, in full_dispatch_request
    rv = self.handle_user_exception(e)
  File "/usr/lib/python2.7/site-packages/flask/app.py", line 1381, in handle_user_exception
    reraise(exc_type, exc_value, tb)
  File "/usr/lib/python2.7/site-packages/flask/app.py", line 1475, in full_dispatch_request
    rv = self.dispatch_request()
  File "/usr/lib/python2.7/site-packages/flask/app.py", line 1461, in dispatch_request
    return self.view_functions[rule.endpoint](**req.view_args)
  File "app.py", line 111, in update_user
    if not User.query.filter_by(id=data['id']).first():
  File "/usr/lib64/python2.7/site-packages/sqlalchemy/orm/query.py", line 2630, in first
    ret = list(self[0:1])
  File "/usr/lib64/python2.7/site-packages/sqlalchemy/orm/query.py", line 2453, in __getitem__
    return list(res)
  File "/usr/lib64/python2.7/site-packages/sqlalchemy/orm/query.py", line 2732, in __iter__
    return self._execute_and_instances(context)
  File "/usr/lib64/python2.7/site-packages/sqlalchemy/orm/query.py", line 2747, in _execute_and_instances
    result = conn.execute(querycontext.statement, self._params)
  File "/usr/lib64/python2.7/site-packages/sqlalchemy/engine/base.py", line 914, in execute
    return meth(self, multiparams, params)
  File "/usr/lib64/python2.7/site-packages/sqlalchemy/sql/elements.py", line 323, in _execute_on_connection
    return connection._execute_clauseelement(self, multiparams, params)
  File "/usr/lib64/python2.7/site-packages/sqlalchemy/engine/base.py", line 1010, in _execute_clauseelement
    compiled_sql, distilled_params
  File "/usr/lib64/python2.7/site-packages/sqlalchemy/engine/base.py", line 1146, in _execute_context
    context)
  File "/usr/lib64/python2.7/site-packages/sqlalchemy/engine/base.py", line 1341, in _handle_dbapi_exception
    exc_info
  File "/usr/lib64/python2.7/site-packages/sqlalchemy/util/compat.py", line 200, in raise_from_cause
    reraise(type(exception), exception, tb=exc_tb)
  File "/usr/lib64/python2.7/site-packages/sqlalchemy/engine/base.py", line 1139, in _execute_context
    context)
  File "/usr/lib64/python2.7/site-packages/sqlalchemy/engine/default.py", line 450, in do_execute
    cursor.execute(statement, parameters)
OperationalError: (sqlite3.OperationalError) no such column: user.x [SQL: u'SELECT user.id AS user_id, user.x AS user_x, user.y AS user_y, user.requested_song AS user_requested_song \nFROM user \nWHERE user.id = ?\n LIMIT ? OFFSET ?'] [parameters: (u'123', 1, 0)]
2017-09-05 00:30:22,080 INFO: errors [in app.py:149]
2017-09-05 00:32:30,694 ERROR: Exception on /api/v1.0/update_user [POST] [in /usr/lib/python2.7/site-packages/flask/app.py:1423]
Traceback (most recent call last):
  File "/usr/lib/python2.7/site-packages/flask/app.py", line 1817, in wsgi_app
    response = self.full_dispatch_request()
  File "/usr/lib/python2.7/site-packages/flask/app.py", line 1475, in full_dispatch_request
    rv = self.dispatch_request()
  File "/usr/lib/python2.7/site-packages/flask/app.py", line 1381, in handle_user_exception
    reraise(exc_type, exc_value, tb)
  File "/usr/lib/python2.7/site-packages/flask/app.py", line 1475, in full_dispatch_request
    rv = self.dispatch_request()
  File "/usr/lib/python2.7/site-packages/flask/app.py", line 1461, in dispatch_request
    return self.view_functions[rule.endpoint](**req.view_args)
  File "app.py", line 111, in update_user
    if not User.query.filter_by(id=data['id']).first():
  File "app.py", line 111, in update_user
    if not User.query.filter_by(id=data['id']).first():
  File "/usr/lib64/python2.7/bdb.py", line 49, in trace_dispatch
    return self.dispatch_line(frame)
  File "/usr/lib64/python2.7/bdb.py", line 68, in dispatch_line
    if self.quitting: raise BdbQuit
BdbQuit
2017-09-05 00:32:33,722 INFO: errors [in app.py:149]
2017-09-05 00:32:40,754 ERROR: Exception on /api/v1.0/update_user [POST] [in /usr/lib/python2.7/site-packages/flask/app.py:1423]
Traceback (most recent call last):
  File "/usr/lib/python2.7/site-packages/flask/app.py", line 1817, in wsgi_app
    response = self.full_dispatch_request()
  File "/usr/lib/python2.7/site-packages/flask/app.py", line 1477, in full_dispatch_request
    rv = self.handle_user_exception(e)
  File "/usr/lib/python2.7/site-packages/flask/app.py", line 1381, in handle_user_exception
    reraise(exc_type, exc_value, tb)
  File "/usr/lib/python2.7/site-packages/flask/app.py", line 1475, in full_dispatch_request
    rv = self.dispatch_request()
  File "/usr/lib/python2.7/site-packages/flask/app.py", line 1461, in dispatch_request
    return self.view_functions[rule.endpoint](**req.view_args)
  File "app.py", line 111, in update_user
    if not User.query.filter_by(id=data['id']).first():
  File "/usr/lib64/python2.7/site-packages/sqlalchemy/orm/query.py", line 2630, in first
    ret = list(self[0:1])
  File "/usr/lib64/python2.7/site-packages/sqlalchemy/orm/query.py", line 2453, in __getitem__
    return list(res)
  File "/usr/lib64/python2.7/site-packages/sqlalchemy/orm/query.py", line 2732, in __iter__
    return self._execute_and_instances(context)
  File "/usr/lib64/python2.7/site-packages/sqlalchemy/orm/query.py", line 2747, in _execute_and_instances
    result = conn.execute(querycontext.statement, self._params)
  File "/usr/lib64/python2.7/site-packages/sqlalchemy/engine/base.py", line 914, in execute
    return meth(self, multiparams, params)
  File "/usr/lib64/python2.7/site-packages/sqlalchemy/sql/elements.py", line 323, in _execute_on_connection
    return connection._execute_clauseelement(self, multiparams, params)
  File "/usr/lib64/python2.7/site-packages/sqlalchemy/engine/base.py", line 1010, in _execute_clauseelement
    compiled_sql, distilled_params
  File "/usr/lib64/python2.7/site-packages/sqlalchemy/engine/base.py", line 1146, in _execute_context
    context)
  File "/usr/lib64/python2.7/site-packages/sqlalchemy/engine/base.py", line 1341, in _handle_dbapi_exception
    exc_info
  File "/usr/lib64/python2.7/site-packages/sqlalchemy/util/compat.py", line 200, in raise_from_cause
    reraise(type(exception), exception, tb=exc_tb)
  File "/usr/lib64/python2.7/site-packages/sqlalchemy/engine/base.py", line 1139, in _execute_context
    context)
  File "/usr/lib64/python2.7/site-packages/sqlalchemy/engine/default.py", line 450, in do_execute
    cursor.execute(statement, parameters)
OperationalError: (sqlite3.OperationalError) no such column: user.phoneid [SQL: u'SELECT user.id AS user_id, user.phoneid AS user_phoneid, user.x AS user_x, user.y AS user_y, user.requested_song AS user_requested_song \nFROM user \nWHERE user.id = ?\n LIMIT ? OFFSET ?'] [parameters: (u'123', 1, 0)]
2017-09-05 00:40:16,114 INFO: errors [in app.py:162]
2017-09-05 00:41:03,982 ERROR: Exception on /api/v1.0/usercount [POST] [in /usr/lib/python2.7/site-packages/flask/app.py:1423]
Traceback (most recent call last):
  File "/usr/lib/python2.7/site-packages/flask/app.py", line 1817, in wsgi_app
    response = self.full_dispatch_request()
  File "/usr/lib/python2.7/site-packages/flask/app.py", line 1477, in full_dispatch_request
    rv = self.handle_user_exception(e)
  File "/usr/lib/python2.7/site-packages/flask/app.py", line 1370, in handle_user_exception
    return self.handle_http_exception(e)
  File "/usr/lib/python2.7/site-packages/flask/app.py", line 1330, in handle_http_exception
    return handler(e)
  File "app.py", line 152, in not_found_error
    return render_template('errors/404.html'), 404
  File "/usr/lib/python2.7/site-packages/flask/templating.py", line 128, in render_template
    context, ctx.app)
  File "/usr/lib/python2.7/site-packages/flask/templating.py", line 110, in _render
    rv = template.render(context)
  File "/usr/lib/python2.7/site-packages/jinja2/environment.py", line 969, in render
    return self.environment.handle_exception(exc_info, True)
  File "/usr/lib/python2.7/site-packages/jinja2/environment.py", line 742, in handle_exception
    reraise(exc_type, exc_value, tb)
  File "/home/sergey/stuff/poke-tuna/templates/errors/404.html", line 1, in top-level template code
    {% extends 'layouts/main.html' %}
  File "/home/sergey/stuff/poke-tuna/templates/layouts/main.html", line 56, in top-level template code
    <li {% if request.endpoint == 'about' %} class="active" {% endif %}><a href="{{ url_for('about') }}">About</a></li>
  File "/usr/lib/python2.7/site-packages/flask/helpers.py", line 312, in url_for
    return appctx.app.handle_url_build_error(error, endpoint, values)
  File "/usr/lib/python2.7/site-packages/flask/app.py", line 1641, in handle_url_build_error
    reraise(exc_type, exc_value, tb)
  File "/usr/lib/python2.7/site-packages/flask/helpers.py", line 305, in url_for
    force_external=external)
  File "/usr/lib/python2.7/site-packages/werkzeug/routing.py", line 1758, in build
    raise BuildError(endpoint, values, method, self)
BuildError: Could not build url for endpoint 'about'. Did you mean 'forgot' instead?
2017-09-05 00:41:17,301 ERROR: Exception on /api/v1.0/usercount [POST] [in /usr/lib/python2.7/site-packages/flask/app.py:1423]
Traceback (most recent call last):
  File "/usr/lib/python2.7/site-packages/flask/app.py", line 1817, in wsgi_app
    response = self.full_dispatch_request()
  File "/usr/lib/python2.7/site-packages/flask/app.py", line 1477, in full_dispatch_request
    rv = self.handle_user_exception(e)
  File "/usr/lib/python2.7/site-packages/flask/app.py", line 1370, in handle_user_exception
    return self.handle_http_exception(e)
  File "/usr/lib/python2.7/site-packages/flask/app.py", line 1330, in handle_http_exception
    return handler(e)
  File "app.py", line 152, in not_found_error
    return render_template('errors/404.html'), 404
  File "/usr/lib/python2.7/site-packages/flask/templating.py", line 128, in render_template
    context, ctx.app)
  File "/usr/lib/python2.7/site-packages/flask/templating.py", line 110, in _render
    rv = template.render(context)
  File "/usr/lib/python2.7/site-packages/jinja2/environment.py", line 969, in render
    return self.environment.handle_exception(exc_info, True)
  File "/usr/lib/python2.7/site-packages/jinja2/environment.py", line 742, in handle_exception
    reraise(exc_type, exc_value, tb)
  File "/home/sergey/stuff/poke-tuna/templates/errors/404.html", line 1, in top-level template code
    {% extends 'layouts/main.html' %}
  File "/home/sergey/stuff/poke-tuna/templates/layouts/main.html", line 56, in top-level template code
    <li {% if request.endpoint == 'about' %} class="active" {% endif %}><a href="{{ url_for('about') }}">About</a></li>
  File "/usr/lib/python2.7/site-packages/flask/helpers.py", line 312, in url_for
    return appctx.app.handle_url_build_error(error, endpoint, values)
  File "/usr/lib/python2.7/site-packages/flask/app.py", line 1641, in handle_url_build_error
    reraise(exc_type, exc_value, tb)
  File "/usr/lib/python2.7/site-packages/flask/helpers.py", line 305, in url_for
    force_external=external)
  File "/usr/lib/python2.7/site-packages/werkzeug/routing.py", line 1758, in build
    raise BuildError(endpoint, values, method, self)
BuildError: Could not build url for endpoint 'about'. Did you mean 'forgot' instead?
2017-09-05 00:42:04,318 INFO: errors [in app.py:164]
2017-09-05 00:42:06,256 ERROR: Exception on /api/v1.0/usercount [POST] [in /usr/lib/python2.7/site-packages/flask/app.py:1423]
Traceback (most recent call last):
  File "/usr/lib/python2.7/site-packages/flask/app.py", line 1817, in wsgi_app
    response = self.full_dispatch_request()
  File "/usr/lib/python2.7/site-packages/flask/app.py", line 1477, in full_dispatch_request
    rv = self.handle_user_exception(e)
  File "/usr/lib/python2.7/site-packages/flask/app.py", line 1370, in handle_user_exception
    return self.handle_http_exception(e)
  File "/usr/lib/python2.7/site-packages/flask/app.py", line 1330, in handle_http_exception
    return handler(e)
  File "app.py", line 154, in not_found_error
    return render_template('errors/404.html'), 404
  File "/usr/lib/python2.7/site-packages/flask/templating.py", line 128, in render_template
    context, ctx.app)
  File "/usr/lib/python2.7/site-packages/flask/templating.py", line 110, in _render
    rv = template.render(context)
  File "/usr/lib/python2.7/site-packages/jinja2/environment.py", line 969, in render
    return self.environment.handle_exception(exc_info, True)
  File "/usr/lib/python2.7/site-packages/jinja2/environment.py", line 742, in handle_exception
    reraise(exc_type, exc_value, tb)
  File "/home/sergey/stuff/poke-tuna/templates/errors/404.html", line 1, in top-level template code
    {% extends 'layouts/main.html' %}
  File "/home/sergey/stuff/poke-tuna/templates/layouts/main.html", line 56, in top-level template code
    <li {% if request.endpoint == 'about' %} class="active" {% endif %}><a href="{{ url_for('about') }}">About</a></li>
  File "/usr/lib/python2.7/site-packages/flask/helpers.py", line 312, in url_for
    return appctx.app.handle_url_build_error(error, endpoint, values)
  File "/usr/lib/python2.7/site-packages/flask/app.py", line 1641, in handle_url_build_error
    reraise(exc_type, exc_value, tb)
  File "/usr/lib/python2.7/site-packages/flask/helpers.py", line 305, in url_for
    force_external=external)
  File "/usr/lib/python2.7/site-packages/werkzeug/routing.py", line 1758, in build
    raise BuildError(endpoint, values, method, self)
BuildError: Could not build url for endpoint 'about'. Did you mean 'forgot' instead?
2017-09-05 00:42:07,940 ERROR: Exception on /api/v1.0/usercount [POST] [in /usr/lib/python2.7/site-packages/flask/app.py:1423]
Traceback (most recent call last):
  File "/usr/lib/python2.7/site-packages/flask/app.py", line 1817, in wsgi_app
    response = self.full_dispatch_request()
  File "/usr/lib/python2.7/site-packages/flask/app.py", line 1477, in full_dispatch_request
    rv = self.handle_user_exception(e)
  File "/usr/lib/python2.7/site-packages/flask/app.py", line 1370, in handle_user_exception
    return self.handle_http_exception(e)
  File "/usr/lib/python2.7/site-packages/flask/app.py", line 1330, in handle_http_exception
    return handler(e)
  File "app.py", line 154, in not_found_error
    return render_template('errors/404.html'), 404
  File "/usr/lib/python2.7/site-packages/flask/templating.py", line 128, in render_template
    context, ctx.app)
  File "/usr/lib/python2.7/site-packages/flask/templating.py", line 110, in _render
    rv = template.render(context)
  File "/usr/lib/python2.7/site-packages/jinja2/environment.py", line 969, in render
    return self.environment.handle_exception(exc_info, True)
  File "/usr/lib/python2.7/site-packages/jinja2/environment.py", line 742, in handle_exception
    reraise(exc_type, exc_value, tb)
  File "/home/sergey/stuff/poke-tuna/templates/errors/404.html", line 1, in top-level template code
    {% extends 'layouts/main.html' %}
  File "/home/sergey/stuff/poke-tuna/templates/layouts/main.html", line 56, in top-level template code
    <li {% if request.endpoint == 'about' %} class="active" {% endif %}><a href="{{ url_for('about') }}">About</a></li>
  File "/usr/lib/python2.7/site-packages/flask/helpers.py", line 312, in url_for
    return appctx.app.handle_url_build_error(error, endpoint, values)
  File "/usr/lib/python2.7/site-packages/flask/app.py", line 1641, in handle_url_build_error
    reraise(exc_type, exc_value, tb)
  File "/usr/lib/python2.7/site-packages/flask/helpers.py", line 305, in url_for
    force_external=external)
  File "/usr/lib/python2.7/site-packages/werkzeug/routing.py", line 1758, in build
    raise BuildError(endpoint, values, method, self)
BuildError: Could not build url for endpoint 'about'. Did you mean 'forgot' instead?
2017-09-05 00:42:23,299 INFO: errors [in app.py:164]
2017-09-05 00:42:26,409 ERROR: Exception on /api/v1.0/usercount [POST] [in /usr/lib/python2.7/site-packages/flask/app.py:1423]
Traceback (most recent call last):
  File "/usr/lib/python2.7/site-packages/flask/app.py", line 1817, in wsgi_app
    response = self.full_dispatch_request()
  File "/usr/lib/python2.7/site-packages/flask/app.py", line 1477, in full_dispatch_request
    rv = self.handle_user_exception(e)
  File "/usr/lib/python2.7/site-packages/flask/app.py", line 1370, in handle_user_exception
    return self.handle_http_exception(e)
  File "/usr/lib/python2.7/site-packages/flask/app.py", line 1330, in handle_http_exception
    return handler(e)
  File "app.py", line 154, in not_found_error
    return render_template('errors/404.html'), 404
  File "/usr/lib/python2.7/site-packages/flask/templating.py", line 128, in render_template
    context, ctx.app)
  File "/usr/lib/python2.7/site-packages/flask/templating.py", line 110, in _render
    rv = template.render(context)
  File "/usr/lib/python2.7/site-packages/jinja2/environment.py", line 969, in render
    return self.environment.handle_exception(exc_info, True)
  File "/usr/lib/python2.7/site-packages/jinja2/environment.py", line 742, in handle_exception
    reraise(exc_type, exc_value, tb)
  File "/home/sergey/stuff/poke-tuna/templates/errors/404.html", line 1, in top-level template code
    {% extends 'layouts/main.html' %}
  File "/home/sergey/stuff/poke-tuna/templates/layouts/main.html", line 56, in top-level template code
    <li {% if request.endpoint == 'about' %} class="active" {% endif %}><a href="{{ url_for('about') }}">About</a></li>
  File "/usr/lib/python2.7/site-packages/flask/helpers.py", line 312, in url_for
    return appctx.app.handle_url_build_error(error, endpoint, values)
  File "/usr/lib/python2.7/site-packages/flask/app.py", line 1641, in handle_url_build_error
    reraise(exc_type, exc_value, tb)
  File "/usr/lib/python2.7/site-packages/flask/helpers.py", line 305, in url_for
    force_external=external)
  File "/usr/lib/python2.7/site-packages/werkzeug/routing.py", line 1758, in build
    raise BuildError(endpoint, values, method, self)
BuildError: Could not build url for endpoint 'about'. Did you mean 'forgot' instead?
2017-09-05 00:43:00,353 INFO: errors [in app.py:162]
2017-09-05 00:43:11,602 ERROR: Exception on /usercount [POST] [in /usr/lib/python2.7/site-packages/flask/app.py:1423]
Traceback (most recent call last):
  File "/usr/lib/python2.7/site-packages/flask/app.py", line 1817, in wsgi_app
    response = self.full_dispatch_request()
  File "/usr/lib/python2.7/site-packages/flask/app.py", line 1478, in full_dispatch_request
    response = self.make_response(rv)
  File "/usr/lib/python2.7/site-packages/flask/app.py", line 1566, in make_response
    raise ValueError('View function did not return a response')
ValueError: View function did not return a response
2017-09-05 00:43:24,013 ERROR: Exception on /usercount [POST] [in /usr/lib/python2.7/site-packages/flask/app.py:1423]
Traceback (most recent call last):
  File "/usr/lib/python2.7/site-packages/flask/app.py", line 1817, in wsgi_app
    response = self.full_dispatch_request()
  File "/usr/lib/python2.7/site-packages/flask/app.py", line 1478, in full_dispatch_request
    response = self.make_response(rv)
  File "/usr/lib/python2.7/site-packages/flask/app.py", line 1566, in make_response
    raise ValueError('View function did not return a response')
ValueError: View function did not return a response
2017-09-05 00:43:51,426 INFO: errors [in app.py:162]
2017-09-05 00:43:53,720 ERROR: Exception on /usercount [POST] [in /usr/lib/python2.7/site-packages/flask/app.py:1423]
Traceback (most recent call last):
  File "/usr/lib/python2.7/site-packages/flask/app.py", line 1817, in wsgi_app
    response = self.full_dispatch_request()
  File "/usr/lib/python2.7/site-packages/flask/app.py", line 1478, in full_dispatch_request
    response = self.make_response(rv)
  File "/usr/lib/python2.7/site-packages/flask/app.py", line 1566, in make_response
    raise ValueError('View function did not return a response')
ValueError: View function did not return a response
2017-09-05 00:43:55,644 ERROR: Exception on /usercount [POST] [in /usr/lib/python2.7/site-packages/flask/app.py:1423]
Traceback (most recent call last):
  File "/usr/lib/python2.7/site-packages/flask/app.py", line 1817, in wsgi_app
    response = self.full_dispatch_request()
  File "/usr/lib/python2.7/site-packages/flask/app.py", line 1478, in full_dispatch_request
    response = self.make_response(rv)
  File "/usr/lib/python2.7/site-packages/flask/app.py", line 1566, in make_response
    raise ValueError('View function did not return a response')
ValueError: View function did not return a response
